<?xml version="1.0" ?>
<!-- =================================================================================== -->
<!-- |    This document was autogenerated by xacro from robinion.xacro                 | -->
<!-- |    EDITING THIS FILE BY HAND IS NOT RECOMMENDED                                 | -->
<!-- =================================================================================== -->
<robot name="robinion">
  <!-- ros_control plugin -->
  <gazebo>
    <plugin filename="libgazebo_ros_control.so" name="gazebo_ros_control">
      <robotNamespace>/robinion</robotNamespace>
      <robotSimType>gazebo_ros_control/DefaultRobotHWSim</robotSimType>
    </plugin>
  </gazebo>
  <!-- Body -->
  <gazebo reference="torso_link">
    <mu1>0.2</mu1>
    <mu2>0.2</mu2>
    <material>Gazebo/White</material>
    <selfCollide>false</selfCollide>
  </gazebo>
  <gazebo reference="upper_body_link">
    <mu1>0.2</mu1>
    <mu2>0.2</mu2>
    <material>Gazebo/White</material>
    <selfCollide>false</selfCollide>
  </gazebo>
  <!-- Head -->
  <gazebo reference="head_yaw_link">
    <mu1>0.2</mu1>
    <mu2>0.2</mu2>
    <material>Gazebo/White</material>
    <selfCollide>false</selfCollide>
  </gazebo>
  <gazebo reference="head_pitch_link">
    <mu1>0.2</mu1>
    <mu2>0.2</mu2>
    <material>Gazebo/White</material>
    <selfCollide>false</selfCollide>
  </gazebo>
  <!-- Tangan Kiri -->
  <gazebo reference="l_shoulder_link">
    <mu1>0.2</mu1>
    <mu2>0.2</mu2>
    <material>Gazebo/White</material>
    <selfCollide>false</selfCollide>
  </gazebo>
  <gazebo reference="l_arm_1_link">
    <mu1>0.2</mu1>
    <mu2>0.2</mu2>
    <material>Gazebo/White</material>
    <selfCollide>false</selfCollide>
  </gazebo>
  <gazebo reference="l_arm_2_link">
    <mu1>0.2</mu1>
    <mu2>0.2</mu2>
    <material>Gazebo/White</material>
    <selfCollide>false</selfCollide>
  </gazebo>
  <gazebo reference="l_arm_3_link">
    <mu1>0.2</mu1>
    <mu2>0.2</mu2>
    <material>Gazebo/White</material>
    <selfCollide>false</selfCollide>
  </gazebo>
  <!-- Tangan Kanan -->
  <gazebo reference="r_shoulder_link">
    <mu1>0.2</mu1>
    <mu2>0.2</mu2>
    <material>Gazebo/White</material>
    <selfCollide>false</selfCollide>
  </gazebo>
  <gazebo reference="r_arm_1_link">
    <mu1>0.2</mu1>
    <mu2>0.2</mu2>
    <material>Gazebo/White</material>
    <selfCollide>false</selfCollide>
  </gazebo>
  <gazebo reference="r_arm_2_link">
    <mu1>0.2</mu1>
    <mu2>0.2</mu2>
    <material>Gazebo/White</material>
    <selfCollide>false</selfCollide>
  </gazebo>
  <gazebo reference="r_arm_3_link">
    <mu1>0.2</mu1>
    <mu2>0.2</mu2>
    <material>Gazebo/White</material>
    <selfCollide>false</selfCollide>
  </gazebo>
  <!-- Kaki Kiri -->
  <gazebo reference="l_hip_yaw_link">
    <mu1>0.2</mu1>
    <mu2>0.2</mu2>
    <material>Gazebo/White</material>
    <selfCollide>false</selfCollide>
  </gazebo>
  <gazebo reference="l_hip_roll_pitch_link">
    <mu1>0.2</mu1>
    <mu2>0.2</mu2>
    <material>Gazebo/White</material>
    <selfCollide>false</selfCollide>
  </gazebo>
  <gazebo reference="l_thigh_back_link">
    <mu1>0.2</mu1>
    <mu2>0.2</mu2>
    <material>Gazebo/White</material>
    <selfCollide>false</selfCollide>
  </gazebo>
  <gazebo reference="l_thigh_front_link">
    <mu1>0.2</mu1>
    <mu2>0.2</mu2>
    <material>Gazebo/White</material>
    <selfCollide>false</selfCollide>
  </gazebo>
  <gazebo reference="l_knee_link">
    <mu1>0.2</mu1>
    <mu2>0.2</mu2>
    <material>Gazebo/White</material>
    <selfCollide>false</selfCollide>
  </gazebo>
  <gazebo reference="l_shank_back_link">
    <mu1>0.2</mu1>
    <mu2>0.2</mu2>
    <material>Gazebo/White</material>
    <selfCollide>false</selfCollide>
  </gazebo>
  <gazebo reference="l_shank_front_link">
    <mu1>0.2</mu1>
    <mu2>0.2</mu2>
    <material>Gazebo/White</material>
    <selfCollide>false</selfCollide>
  </gazebo>
  <gazebo reference="l_ankle_roll_pitch_link">
    <mu1>0.2</mu1>
    <mu2>0.2</mu2>
    <material>Gazebo/White</material>
    <selfCollide>false</selfCollide>
  </gazebo>
  <gazebo reference="l_foot_link">
    <kp>100000.0</kp>
    <kd>100.0</kd>
    <mu1>1.5</mu1>
    <mu2>1.5</mu2>
    <fdir1>1 0 0</fdir1>
    <maxVel>1.0</maxVel>
    <minDepth>0.001</minDepth>
    <material>Gazebo/White</material>
    <selfCollide>false</selfCollide>
  </gazebo>
  <!-- right leg links -->
  <gazebo reference="r_hip_yaw_link">
    <mu1>0.2</mu1>
    <mu2>0.2</mu2>
    <material>Gazebo/White</material>
    <selfCollide>false</selfCollide>
  </gazebo>
  <gazebo reference="r_hip_roll_pitch_link">
    <mu1>0.2</mu1>
    <mu2>0.2</mu2>
    <material>Gazebo/White</material>
    <selfCollide>false</selfCollide>
  </gazebo>
  <gazebo reference="r_thigh_back_link">
    <mu1>0.2</mu1>
    <mu2>0.2</mu2>
    <material>Gazebo/White</material>
    <selfCollide>false</selfCollide>
  </gazebo>
  <gazebo reference="r_thigh_front_link">
    <mu1>0.2</mu1>
    <mu2>0.2</mu2>
    <material>Gazebo/White</material>
    <selfCollide>false</selfCollide>
  </gazebo>
  <gazebo reference="r_knee_link">
    <mu1>0.2</mu1>
    <mu2>0.2</mu2>
    <material>Gazebo/White</material>
    <selfCollide>false</selfCollide>
  </gazebo>
  <gazebo reference="r_shank_back_link">
    <mu1>0.2</mu1>
    <mu2>0.2</mu2>
    <material>Gazebo/White</material>
    <selfCollide>false</selfCollide>
  </gazebo>
  <gazebo reference="r_shank_front_link">
    <mu1>0.2</mu1>
    <mu2>0.2</mu2>
    <material>Gazebo/White</material>
    <selfCollide>false</selfCollide>
  </gazebo>
  <gazebo reference="r_ankle_roll_pitch_link">
    <mu1>0.2</mu1>
    <mu2>0.2</mu2>
    <material>Gazebo/White</material>
    <selfCollide>false</selfCollide>
  </gazebo>
  <gazebo reference="r_foot_link">
    <kp>100000.0</kp>
    <kd>100.0</kd>
    <mu1>1.5</mu1>
    <mu2>1.5</mu2>
    <fdir1>1 0 0</fdir1>
    <maxVel>1.0</maxVel>
    <minDepth>0.001</minDepth>
    <material>Gazebo/White</material>
    <selfCollide>false</selfCollide>
  </gazebo>
  <gazebo reference="gaze_link">
    <sensor name="camera" type="camera">
      <camera name="__default__">
        <horizontal_fov>1.012300</horizontal_fov>
        <image>
          <width>320</width>
          <height>240</height>
        </image>
        <clip>
          <near>0.001000</near>
          <far>100.000000</far>
        </clip>
      </camera>
      <always_on>1</always_on>
      <update_rate>30.000000</update_rate>
      <visualize>1</visualize>
      <plugin filename="libgazebo_ros_camera.so" name="camera_controller">
        <alwaysOn>true</alwaysOn>
        <updateRate>30</updateRate>
        <cameraName>robinion/camera</cameraName>
        <imageTopicName>image_raw</imageTopicName>
        <cameraInfoTopicName>camera_info</cameraInfoTopicName>
        <frameName>cam_link</frameName>
        <hackBaseline>0.07</hackBaseline>
        <distortionK1>0.0</distortionK1>
        <distortionK2>0.0</distortionK2>
        <distortionK3>0.0</distortionK3>
        <distortionT1>0.0</distortionT1>
        <distortionT2>0.0</distortionT2>
      </plugin>
    </sensor>
  </gazebo>
  <gazebo reference="imu_link">
    <gravity>true</gravity>
    <sensor name="imu_sensor" type="imu">
      <always_on>true</always_on>
      <update_rate>125</update_rate>
      <visualize>true</visualize>
      <topic>__default_topic__</topic>
      <plugin filename="libgazebo_ros_imu_sensor.so" name="imu_plugin">
        <topicName>robinion/imu</topicName>
        <bodyName>imu_link</bodyName>
        <updateRateHZ>125.0</updateRateHZ>
        <gaussianNoise>0.0</gaussianNoise>
        <xyzOffset>0 0 0</xyzOffset>
        <rpyOffset>0 0 0</rpyOffset>
        <frameName>imu_link</frameName>
      </plugin>
    </sensor>
  </gazebo>
  <!-- <xacro:property name="pi" value="3.141592654" /> -->
  <!-- <xacro:property name="pi" value="3.141592654" /> -->
  <link name="base_link">
    </link>
  <joint name="base_fixed_joint" type="fixed">
    <parent link="base_link"/>
    <child link="torso_link"/>
    <origin rpy="0 0 0" xyz="0.000 0.000 0.000"/>
  </joint>
  <link name="torso_link">
    <collision>
      <origin rpy="0.00 0.00 0.00" xyz="0.00 0.00 0.00"/>
      <geometry>
        <mesh filename="package://robinion_description/meshes/collision/lower_body_collision.stl"/>
      </geometry>
    </collision>
    <visual>
      <origin rpy="0.00 0.00 0.00" xyz="0.00 0.00 0.00"/>
      <geometry>
        <mesh filename="package://robinion_description/meshes/visual/lower_body_visual.stl"/>
      </geometry>
    </visual>
    <inertial>
      <origin rpy="0.00 0.00 0.00" xyz="-0.007122 0.000256 0.034914"/>
      <mass value="0.960747"/>
      <inertia ixx="0.002662" ixy="0.000002" ixz="0.000113" iyy="0.001197" iyz="0.000003" izz="0.002578"/>
    </inertial>
  </link>
  <joint name="torso_pitch_joint" type="revolute">
    <parent link="torso_link"/>
    <child link="upper_body_link"/>
    <origin rpy="0 0 0" xyz="0.019 0.0245 0.07075"/>
    <axis xyz="0 1 0"/>
    <limit effort="10.6" lower="-0.52" upper="1.570796327" velocity="3.14"/>
    <!-- <limit velocity="3.14" effort="100" lower="-3" upper="3" /> -->
    <dynamics damping="0.1" friction="0.0"/>
    <implicitSpringDamper>True</implicitSpringDamper>
  </joint>
  <transmission name="torso_pitch_joint_tran">
    <type>transmission_interface/SimpleTransmission</type>
    <joint name="torso_pitch_joint">
      <hardwareInterface>hardware_interface/EffortJointInterface</hardwareInterface>
    </joint>
    <actuator name="torso_pitch_joint_motor">
      <hardwareInterface>hardware_interface/EffortJointInterface</hardwareInterface>
      <mechanicalReduction>1</mechanicalReduction>
    </actuator>
  </transmission>
  <link name="upper_body_link">
    <collision>
      <origin rpy="0.00 0.00 0.00" xyz="0.00 0.00 0.00"/>
      <geometry>
        <mesh filename="package://robinion_description/meshes/collision/upper_body_collision.stl"/>
      </geometry>
    </collision>
    <visual>
      <origin rpy="0.00 0.00 0.00" xyz="0.00 0.00 0.00"/>
      <geometry>
        <mesh filename="package://robinion_description/meshes/visual/upper_body_visual.stl"/>
      </geometry>
    </visual>
    <inertial>
      <origin rpy="0.00 0.00 0.00" xyz="-0.029870 -0.024411 0.123492"/>
      <mass value="1.234139"/>
      <inertia ixx="0.006795" ixy="0.000000" ixz="-0.000098" iyy="0.003101" iyz="-0.000005" izz="0.006100"/>
    </inertial>
  </link>
  <joint name="imu_fixed_joint" type="fixed">
    <parent link="upper_body_link"/>
    <child link="imu_link"/>
    <origin rpy="0 0 0" xyz="-0.021 -0.025 0.122"/>
  </joint>
  <link name="imu_link">
    </link>
  <joint name="head_yaw_joint" type="revolute">
    <parent link="upper_body_link"/>
    <child link="head_yaw_link"/>
    <origin rpy="0 0 0" xyz="-0.0125 -0.0245 0.183051"/>
    <axis xyz="0 0 1"/>
    <limit effort="4.1" lower="-1.570796327" upper="1.570796327" velocity="4.82"/>
    <!-- <limit velocity="4.82" effort="1000" lower="-3" upper="3" /> -->
    <dynamics damping="0.1" friction="0.0"/>
    <implicitSpringDamper>True</implicitSpringDamper>
  </joint>
  <transmission name="head_yaw_joint_tran">
    <type>transmission_interface/SimpleTransmission</type>
    <joint name="head_yaw_joint">
      <hardwareInterface>hardware_interface/EffortJointInterface</hardwareInterface>
    </joint>
    <actuator name="head_yaw_joint_motor">
      <hardwareInterface>hardware_interface/EffortJointInterface</hardwareInterface>
      <mechanicalReduction>1</mechanicalReduction>
    </actuator>
  </transmission>
  <link name="head_yaw_link">
    <collision>
      <origin rpy="0.00 0.00 0.00" xyz="0.00 0.00 0.00"/>
      <geometry>
        <mesh filename="package://robinion_description/meshes/collision/head_yaw_collision.stl"/>
      </geometry>
    </collision>
    <visual>
      <origin rpy="0.00 0.00 0.00" xyz="0.00 0.00 0.00"/>
      <geometry>
        <mesh filename="package://robinion_description/meshes/visual/standard/head_yaw_visual.stl"/>
      </geometry>
    </visual>
    <inertial>
      <origin rpy="0.00 0.00 0.00" xyz="0.000000 0.000000 0.015679"/>
      <mass value="0.017180"/>
      <inertia ixx="0.000009" ixy="0.000000" ixz="0.000000" iyy="0.000005" iyz="0.000000" izz="0.000006"/>
    </inertial>
  </link>
  <joint name="head_pitch_joint" type="revolute">
    <parent link="head_yaw_link"/>
    <child link="head_pitch_link"/>
    <origin rpy="0 0 0" xyz="0.000 0.019 0.047"/>
    <axis xyz="0 -1 0"/>
    <limit effort="4.1" lower="-1.570796327" upper="1.570796327" velocity="4.82"/>
    <!-- <limit velocity="4.82" effort="1000" lower="-3" upper="3" /> -->
    <dynamics damping="0.1" friction="0.0"/>
    <implicitSpringDamper>True</implicitSpringDamper>
  </joint>
  <transmission name="head_pitch_joint_tran">
    <type>transmission_interface/SimpleTransmission</type>
    <joint name="head_pitch_joint">
      <hardwareInterface>hardware_interface/EffortJointInterface</hardwareInterface>
    </joint>
    <actuator name="head_pitch_joint_motor">
      <hardwareInterface>hardware_interface/EffortJointInterface</hardwareInterface>
      <mechanicalReduction>1</mechanicalReduction>
    </actuator>
  </transmission>
  <link name="head_pitch_link">
    <collision>
      <origin rpy="0.00 0.00 0.00" xyz="0.00 0.00 0.00"/>
      <geometry>
        <mesh filename="package://robinion_description/meshes/collision/head_pitch_collision.stl"/>
      </geometry>
    </collision>
    <visual>
      <origin rpy="0.00 0.00 0.00" xyz="0.00 0.00 0.00"/>
      <geometry>
        <mesh filename="package://robinion_description/meshes/visual/standard/head_pitch_visual.stl"/>
      </geometry>
    </visual>
    <inertial>
      <origin rpy="0.00 0.00 0.00" xyz="0.000985 -0.018216 0.022305"/>
      <mass value="0.164500"/>
      <inertia ixx="0.000115" ixy="0.000000" ixz="0.000005" iyy="0.000092" iyz="0.000001" izz="0.000047"/>
    </inertial>
  </link>
  <joint name="cam_fixed_joint" type="fixed">
    <parent link="head_pitch_link"/>
    <child link="cam_link"/>
    <origin rpy="-1.5708 0 -1.5708" xyz="0.019 -0.019 0.054"/>
  </joint>
  <link name="cam_link">
		</link>
  <joint name="gaze_fixed_joint" type="fixed">
    <parent link="head_pitch_link"/>
    <child link="gaze_link"/>
    <origin rpy="0 0 0" xyz="0.019 -0.019 0.054"/>
  </joint>
  <link name="gaze_link">
		</link>
  <joint name="l_shoulder_pitch_joint" type="revolute">
    <parent link="upper_body_link"/>
    <child link="l_shoulder_link"/>
    <origin rpy="0 0 0" xyz="-0.02089 0.0815 0.1388"/>
    <axis xyz="0 1 0"/>
    <limit effort="10.6" lower="-2.8274333886000003" upper="2.8274333886000003" velocity="3.14"/>
    <!-- <limit velocity="3.14" effort="100" lower="-3" upper="3" /> -->
    <dynamics damping="0.1" friction="0.0"/>
    <implicitSpringDamper>True</implicitSpringDamper>
  </joint>
  <transmission name="l_shoulder_pitch_joint_tran">
    <type>transmission_interface/SimpleTransmission</type>
    <joint name="l_shoulder_pitch_joint">
      <hardwareInterface>hardware_interface/EffortJointInterface</hardwareInterface>
    </joint>
    <actuator name="l_shoulder_pitch_joint_motor">
      <hardwareInterface>hardware_interface/EffortJointInterface</hardwareInterface>
      <mechanicalReduction>1</mechanicalReduction>
    </actuator>
  </transmission>
  <link name="l_shoulder_link">
    <collision>
      <origin rpy="0.00 0.00 0.00" xyz="0.00 0.00 0.00"/>
      <geometry>
        <mesh filename="package://robinion_description/meshes/collision/l_shoulder_collision.stl"/>
      </geometry>
    </collision>
    <visual>
      <origin rpy="0.00 0.00 0.00" xyz="0.00 0.00 0.00"/>
      <geometry>
        <mesh filename="package://robinion_description/meshes/visual/standard/left_shoulder_visual.stl"/>
      </geometry>
    </visual>
    <inertial>
      <origin rpy="0.00 0.00 0.00" xyz="0.000000 0.010235 -0.004313"/>
      <mass value="0.044923"/>
      <inertia ixx="0.000013" ixy="0.000000" ixz="0.000000" iyy="0.000027" iyz="-0.000003" izz="0.000025"/>
    </inertial>
  </link>
  <joint name="l_shoulder_roll_joint" type="revolute">
    <parent link="l_shoulder_link"/>
    <child link="l_arm_1_link"/>
    <origin rpy="0 0 0" xyz="0.0245 0.030017 -0.022"/>
    <axis xyz="-1 0 0"/>
    <limit effort="10.6" lower="-1.570796327" upper="1.570796327" velocity="3.14"/>
    <!-- <limit velocity="3.14" effort="100" lower="-3" upper="3" /> -->
    <dynamics damping="0.1" friction="0.0"/>
    <implicitSpringDamper>True</implicitSpringDamper>
  </joint>
  <transmission name="l_shoulder_roll_joint_tran">
    <type>transmission_interface/SimpleTransmission</type>
    <joint name="l_shoulder_roll_joint">
      <hardwareInterface>hardware_interface/EffortJointInterface</hardwareInterface>
    </joint>
    <actuator name="l_shoulder_roll_joint_motor">
      <hardwareInterface>hardware_interface/EffortJointInterface</hardwareInterface>
      <mechanicalReduction>1</mechanicalReduction>
    </actuator>
  </transmission>
  <link name="l_arm_1_link">
    <collision>
      <origin rpy="0.00 0.00 0.00" xyz="0.00 0.00 0.00"/>
      <geometry>
        <mesh filename="package://robinion_description/meshes/collision/l_arm_1_collision.stl"/>
      </geometry>
    </collision>
    <visual>
      <origin rpy="0.00 0.00 0.00" xyz="0.00 0.00 0.00"/>
      <geometry>
        <mesh filename="package://robinion_description/meshes/visual/l_arm_1_visual.stl"/>
      </geometry>
    </visual>
    <inertial>
      <origin rpy="0.00 0.00 0.00" xyz="-0.027891 0.046707 0.000000"/>
      <mass value="0.389041"/>
      <inertia ixx="0.000698" ixy="-0.000079" ixz="0.000000" iyy="0.000117" iyz="0.000000" izz="0.000753"/>
    </inertial>
  </link>
  <joint name="l_elbow_pitch_joint" type="revolute">
    <parent link="l_arm_1_link"/>
    <child link="l_arm_2_link"/>
    <origin rpy="0 0 0" xyz="-0.0245 0.118 0.000"/>
    <axis xyz="0 1 0"/>
    <limit effort="4.1" lower="-2.8274333886000003" upper="2.8274333886000003" velocity="4.82"/>
    <!-- <limit velocity="4.82" effort="100" lower="-3" upper="3" /> -->
    <dynamics damping="0.1" friction="0.0"/>
    <implicitSpringDamper>True</implicitSpringDamper>
  </joint>
  <transmission name="l_elbow_pitch_joint_tran">
    <type>transmission_interface/SimpleTransmission</type>
    <joint name="l_elbow_pitch_joint">
      <hardwareInterface>hardware_interface/EffortJointInterface</hardwareInterface>
    </joint>
    <actuator name="l_elbow_pitch_joint_motor">
      <hardwareInterface>hardware_interface/EffortJointInterface</hardwareInterface>
      <mechanicalReduction>1</mechanicalReduction>
    </actuator>
  </transmission>
  <link name="l_arm_2_link">
    <collision>
      <origin rpy="0.00 0.00 0.00" xyz="0.00 0.00 0.00"/>
      <geometry>
        <mesh filename="package://robinion_description/meshes/collision/l_arm_2_collision.stl"/>
      </geometry>
    </collision>
    <visual>
      <origin rpy="0.00 0.00 0.00" xyz="0.00 0.00 0.00"/>
      <geometry>
        <mesh filename="package://robinion_description/meshes/visual/l_arm_2_visual.stl"/>
      </geometry>
    </visual>
    <inertial>
      <origin rpy="0.00 0.00 0.00" xyz="0.003756 0.032656 0.000000"/>
      <mass value="0.051730"/>
      <inertia ixx="0.000036" ixy="0.000005" ixz="0.000000" iyy="0.000028" iyz="0.000000" izz="0.000025"/>
    </inertial>
  </link>
  <joint name="l_elbow_yaw_joint" type="revolute">
    <parent link="l_arm_2_link"/>
    <child link="l_arm_3_link"/>
    <origin rpy="0 0 0" xyz="0.022 0.060 0.0245"/>
    <axis xyz="0 0 -1"/>
    <limit effort="10.6" lower="-1.570796327" upper="1.570796327" velocity="3.14"/>
    <!-- <limit velocity="3.14" effort="100" lower="-3" upper="3" /> -->
    <dynamics damping="0.1" friction="0.0"/>
    <implicitSpringDamper>True</implicitSpringDamper>
  </joint>
  <transmission name="l_elbow_yaw_joint_tran">
    <type>transmission_interface/SimpleTransmission</type>
    <joint name="l_elbow_yaw_joint">
      <hardwareInterface>hardware_interface/EffortJointInterface</hardwareInterface>
    </joint>
    <actuator name="l_elbow_yaw_joint_motor">
      <hardwareInterface>hardware_interface/EffortJointInterface</hardwareInterface>
      <mechanicalReduction>1</mechanicalReduction>
    </actuator>
  </transmission>
  <link name="l_arm_3_link">
    <collision>
      <origin rpy="0.00 0.00 0.00" xyz="0.00 0.00 0.00"/>
      <geometry>
        <mesh filename="package://robinion_description/meshes/collision/l_arm_3_collision.stl"/>
      </geometry>
    </collision>
    <visual>
      <origin rpy="0.00 0.00 0.00" xyz="0.00 0.00 0.00"/>
      <geometry>
        <mesh filename="package://robinion_description/meshes/visual/l_arm_3_visual.stl"/>
      </geometry>
    </visual>
    <inertial>
      <origin rpy="0.00 0.00 0.00" xyz="0.000000 0.018081 -0.023869"/>
      <mass value="0.246669"/>
      <inertia ixx="0.000135" ixy="0.000000" ixz="0.000000" iyy="0.000064" iyz="-0.000001" izz="0.000121"/>
    </inertial>
  </link>
  <!-- <joint name="l_wrist_fixed_joint" type="fixed">
			<parent link="l_arm_3_link"/>
			<child link="l_wrist"/>
			<origin xyz="0.000 0.068 -0.0245" rpy="0 0 0"/>
		</joint>

		<link name="l_wrist">
		</link> -->
  <joint name="l_gripper_fixed_joint" type="fixed">
    <parent link="l_arm_3_link"/>
    <child link="l_gripper"/>
    <origin rpy="0 0 0" xyz="0.000 0.068 -0.0245"/>
  </joint>
  <link name="l_gripper">
    <collision>
      <origin rpy="0.00 0.00 0.00" xyz="0.00 0.00 0.00"/>
      <geometry>
        <mesh filename="package://robinion_description/meshes/collision/l_gripper_collision.stl"/>
      </geometry>
    </collision>
    <visual>
      <origin rpy="0.00 0.00 0.00" xyz="0.00 0.00 0.00"/>
      <geometry>
        <mesh filename="package://robinion_description/meshes/visual/standard/left_gripper_visual.stl"/>
      </geometry>
    </visual>
    <inertial>
      <origin rpy="0.00 0.00 0.00" xyz="0.000002 0.043774 0.003217"/>
      <mass value="0.216195"/>
      <inertia ixx="0.000183" ixy="0.000000" ixz="0.000000" iyy="0.000104" iyz="0.000015" izz="0.000191"/>
    </inertial>
  </link>
  <joint name="r_shoulder_pitch_joint" type="revolute">
    <parent link="upper_body_link"/>
    <child link="r_shoulder_link"/>
    <origin rpy="0 0 0" xyz="-0.02089 -0.1305 0.1388"/>
    <axis xyz="0 -1 0"/>
    <limit effort="10.6" lower="-2.8274333886000003" upper="2.8274333886000003" velocity="3.14"/>
    <!-- <limit velocity="3.14" effort="100" lower="-3" upper="3" /> -->
    <dynamics damping="0.1" friction="0.0"/>
    <implicitSpringDamper>True</implicitSpringDamper>
  </joint>
  <transmission name="r_shoulder_pitch_joint_tran">
    <type>transmission_interface/SimpleTransmission</type>
    <joint name="r_shoulder_pitch_joint">
      <hardwareInterface>hardware_interface/EffortJointInterface</hardwareInterface>
    </joint>
    <actuator name="r_shoulder_pitch_joint_motor">
      <hardwareInterface>hardware_interface/EffortJointInterface</hardwareInterface>
      <mechanicalReduction>1</mechanicalReduction>
    </actuator>
  </transmission>
  <link name="r_shoulder_link">
    <collision>
      <origin rpy="0.00 0.00 0.00" xyz="0.00 0.00 0.00"/>
      <geometry>
        <mesh filename="package://robinion_description/meshes/collision/r_shoulder_collision.stl"/>
      </geometry>
    </collision>
    <visual>
      <origin rpy="0.00 0.00 0.00" xyz="0.00 0.00 0.00"/>
      <geometry>
        <mesh filename="package://robinion_description/meshes/visual/standard/right_shoulder_visual.stl"/>
      </geometry>
    </visual>
    <inertial>
      <origin rpy="0.00 0.00 0.00" xyz="-0.000000 -0.010235 -0.004313"/>
      <mass value="0.044923"/>
      <inertia ixx="0.000013" ixy="0.000000" ixz="0.000000" iyy="0.000027" iyz="0.000003" izz="0.000025"/>
    </inertial>
  </link>
  <joint name="r_shoulder_roll_joint" type="revolute">
    <parent link="r_shoulder_link"/>
    <child link="r_arm_1_link"/>
    <origin rpy="0 0 0" xyz="0.0245 -0.030017 -0.022"/>
    <axis xyz="-1 0 0"/>
    <limit effort="10.6" lower="-1.570796327" upper="1.570796327" velocity="3.14"/>
    <!-- <limit velocity="3.14" effort="100" lower="-3" upper="3" /> -->
    <dynamics damping="0.1" friction="0.0"/>
    <implicitSpringDamper>True</implicitSpringDamper>
  </joint>
  <transmission name="r_shoulder_roll_joint_tran">
    <type>transmission_interface/SimpleTransmission</type>
    <joint name="r_shoulder_roll_joint">
      <hardwareInterface>hardware_interface/EffortJointInterface</hardwareInterface>
    </joint>
    <actuator name="r_shoulder_roll_joint_motor">
      <hardwareInterface>hardware_interface/EffortJointInterface</hardwareInterface>
      <mechanicalReduction>1</mechanicalReduction>
    </actuator>
  </transmission>
  <link name="r_arm_1_link">
    <collision>
      <origin rpy="0.00 0.00 0.00" xyz="0.00 0.00 0.00"/>
      <geometry>
        <mesh filename="package://robinion_description/meshes/collision/r_arm_1_collision.stl"/>
      </geometry>
    </collision>
    <visual>
      <origin rpy="0.00 0.00 0.00" xyz="0.00 0.00 0.00"/>
      <geometry>
        <mesh filename="package://robinion_description/meshes/visual/r_arm_1_visual.stl"/>
      </geometry>
    </visual>
    <inertial>
      <origin rpy="0.00 0.00 0.00" xyz="-0.027884 -0.046707 0.000000"/>
      <mass value="0.389041"/>
      <inertia ixx="0.000698" ixy="0.000079" ixz="0.000000" iyy="0.000117" iyz="0.000000" izz="0.000753"/>
    </inertial>
  </link>
  <joint name="r_elbow_pitch_joint" type="revolute">
    <parent link="r_arm_1_link"/>
    <child link="r_arm_2_link"/>
    <origin rpy="0 0 0" xyz="-0.0245 -0.118 0.000"/>
    <axis xyz="0 -1 0"/>
    <limit effort="4.1" lower="-2.8274333886000003" upper="2.8274333886000003" velocity="4.82"/>
    <!-- <limit velocity="4.82" effort="100" lower="-3" upper="3" /> -->
    <dynamics damping="0.1" friction="0.0"/>
    <implicitSpringDamper>True</implicitSpringDamper>
  </joint>
  <transmission name="r_elbow_pitch_joint_tran">
    <type>transmission_interface/SimpleTransmission</type>
    <joint name="r_elbow_pitch_joint">
      <hardwareInterface>hardware_interface/EffortJointInterface</hardwareInterface>
    </joint>
    <actuator name="r_elbow_pitch_joint_motor">
      <hardwareInterface>hardware_interface/EffortJointInterface</hardwareInterface>
      <mechanicalReduction>1</mechanicalReduction>
    </actuator>
  </transmission>
  <link name="r_arm_2_link">
    <collision>
      <origin rpy="0.00 0.00 0.00" xyz="0.00 0.00 0.00"/>
      <geometry>
        <mesh filename="package://robinion_description/meshes/collision/r_arm_2_collision.stl"/>
      </geometry>
    </collision>
    <visual>
      <origin rpy="0.00 0.00 0.00" xyz="0.00 0.00 0.00"/>
      <geometry>
        <mesh filename="package://robinion_description/meshes/visual/r_arm_2_visual.stl"/>
      </geometry>
    </visual>
    <inertial>
      <origin rpy="0.00 0.00 0.00" xyz="0.003756 -0.032656 0.000000"/>
      <mass value="0.051730"/>
      <inertia ixx="0.000036" ixy="-0.000005" ixz="0.000000" iyy="0.000028" iyz="0.000000" izz="0.000025"/>
    </inertial>
  </link>
  <joint name="r_elbow_yaw_joint" type="revolute">
    <parent link="r_arm_2_link"/>
    <child link="r_arm_3_link"/>
    <origin rpy="0 0 0" xyz="0.022 -0.060 0.0245"/>
    <axis xyz="0 0 -1"/>
    <limit effort="10.6" lower="-1.570796327" upper="1.570796327" velocity="3.14"/>
    <!-- <limit velocity="3.14" effort="100" lower="-3" upper="3" /> -->
    <dynamics damping="0.1" friction="0.0"/>
    <implicitSpringDamper>True</implicitSpringDamper>
  </joint>
  <transmission name="r_elbow_yaw_joint_tran">
    <type>transmission_interface/SimpleTransmission</type>
    <joint name="r_elbow_yaw_joint">
      <hardwareInterface>hardware_interface/EffortJointInterface</hardwareInterface>
    </joint>
    <actuator name="r_elbow_yaw_joint_motor">
      <hardwareInterface>hardware_interface/EffortJointInterface</hardwareInterface>
      <mechanicalReduction>1</mechanicalReduction>
    </actuator>
  </transmission>
  <link name="r_arm_3_link">
    <collision>
      <origin rpy="0.00 0.00 0.00" xyz="0.00 0.00 0.00"/>
      <geometry>
        <mesh filename="package://robinion_description/meshes/collision/r_arm_3_collision.stl"/>
      </geometry>
    </collision>
    <visual>
      <origin rpy="0.00 0.00 0.00" xyz="0.00 0.00 0.00"/>
      <geometry>
        <mesh filename="package://robinion_description/meshes/visual/r_arm_3_visual.stl"/>
      </geometry>
    </visual>
    <inertial>
      <origin rpy="0.00 0.00 0.00" xyz="0.000000 -0.018081 -0.023869"/>
      <mass value="0.246669"/>
      <inertia ixx="0.000135" ixy="0.000000" ixz="0.000000" iyy="0.000064" iyz="0.000001" izz="0.000121"/>
    </inertial>
  </link>
  <!-- <joint name="r_wrist_fixed_joint" type="fixed">
			<parent link="r_arm_3_link"/>
			<child link="r_wrist"/>
			<origin xyz="0.000 -0.068 -0.025" rpy="0 0 0"/>
		</joint>

		<link name="r_wrist">
		</link> -->
  <joint name="r_gripper_fixed_joint" type="fixed">
    <parent link="r_arm_3_link"/>
    <child link="r_gripper"/>
    <origin rpy="0 0 0" xyz="0.000 -0.068 -0.0245"/>
  </joint>
  <link name="r_gripper">
    <collision>
      <origin rpy="0.00 0.00 0.00" xyz="0.00 0.00 0.00"/>
      <geometry>
        <mesh filename="package://robinion_description/meshes/collision/r_gripper_collision.stl"/>
      </geometry>
    </collision>
    <visual>
      <origin rpy="0.00 0.00 0.00" xyz="0.00 0.00 0.00"/>
      <geometry>
        <mesh filename="package://robinion_description/meshes/visual/standard/right_gripper_visual.stl"/>
      </geometry>
    </visual>
    <inertial>
      <origin rpy="0.00 0.00 0.00" xyz="-0.000002 -0.043774 0.003217"/>
      <mass value="0.216195"/>
      <inertia ixx="0.000183" ixy="0.000000" ixz="0.000000" iyy="0.000104" iyz="-0.000015" izz="0.000191"/>
    </inertial>
  </link>
  <joint name="l_hip_yaw_joint" type="revolute">
    <parent link="base_link"/>
    <child link="l_hip_yaw_link"/>
    <origin rpy="0 0 0" xyz="0.000 0.055 -0.006"/>
    <axis xyz="0 0 -1"/>
    <limit effort="10.6" lower="-2.8274333886000003" upper="2.8274333886000003" velocity="3.14"/>
    <!-- <limit velocity="3.14" effort="100" lower="-3" upper="3" /> -->
    <dynamics damping="0.1" friction="0.0"/>
    <implicitSpringDamper>True</implicitSpringDamper>
  </joint>
  <transmission name="l_hip_yaw_joint_tran">
    <type>transmission_interface/SimpleTransmission</type>
    <joint name="l_hip_yaw_joint">
      <hardwareInterface>hardware_interface/EffortJointInterface</hardwareInterface>
    </joint>
    <actuator name="l_hip_yaw_joint_motor">
      <hardwareInterface>hardware_interface/EffortJointInterface</hardwareInterface>
      <mechanicalReduction>1</mechanicalReduction>
    </actuator>
  </transmission>
  <link name="l_hip_yaw_link">
    <collision>
      <origin rpy="0.00 0.00 0.00" xyz="0.00 0.00 0.00"/>
      <geometry>
        <mesh filename="package://robinion_description/meshes/collision/l_hip_yaw_collision.stl"/>
      </geometry>
    </collision>
    <visual>
      <origin rpy="0.00 0.00 0.00" xyz="0.00 0.00 0.00"/>
      <geometry>
        <mesh filename="package://robinion_description/meshes/visual/l_hip_yaw_visual.stl"/>
      </geometry>
    </visual>
    <inertial>
      <origin rpy="0.00 0.00 0.00" xyz="0.002613 0.000000 -0.016031"/>
      <mass value="0.048671"/>
      <inertia ixx="0.000020" ixy="0.000000" ixz="0.000000" iyy="0.000089" iyz="0.000000" izz="0.000080"/>
    </inertial>
  </link>
  <joint name="l_hip_roll_joint" type="revolute">
    <parent link="l_hip_yaw_link"/>
    <child link="l_hip_roll_pitch_link"/>
    <origin rpy="0 0 0" xyz="-0.042125 0.000 -0.050"/>
    <axis xyz="-1 0 0"/>
    <limit effort="9.90" lower="-0.7853981635" upper="0.7853981635" velocity="4.08"/>
    <!-- <limit velocity="4.08" effort="100" lower="-3" upper="3" /> -->
    <dynamics damping="0.1" friction="0.0"/>
    <implicitSpringDamper>True</implicitSpringDamper>
  </joint>
  <transmission name="l_hip_roll_joint_tran">
    <type>transmission_interface/SimpleTransmission</type>
    <joint name="l_hip_roll_joint">
      <hardwareInterface>hardware_interface/EffortJointInterface</hardwareInterface>
    </joint>
    <actuator name="l_hip_roll_joint_motor">
      <hardwareInterface>hardware_interface/EffortJointInterface</hardwareInterface>
      <mechanicalReduction>1</mechanicalReduction>
    </actuator>
  </transmission>
  <link name="l_hip_roll_pitch_link">
    <collision>
      <origin rpy="0.00 0.00 0.00" xyz="0.09 0.00 0.00"/>
      <geometry>
        <mesh filename="package://robinion_description/meshes/collision/l_hip_roll_pitch_collision.stl"/>
      </geometry>
    </collision>
    <visual>
      <origin rpy="0.00 0.00 0.00" xyz="0.00 0.00 0.00"/>
      <geometry>
        <mesh filename="package://robinion_description/meshes/visual/standard/left_hip_roll_pitch_visual.stl"/>
      </geometry>
    </visual>
    <inertial>
      <origin rpy="0.00 0.00 0.00" xyz="0.045037 0.000333 -0.015045"/>
      <mass value="0.467377"/>
      <inertia ixx="0.000198" ixy="0.000003" ixz="0.000001" iyy="0.000406" iyz="0.000000" izz="0.000326"/>
    </inertial>
  </link>
  <joint name="l_hip_pitch_joint" type="revolute">
    <parent link="l_hip_roll_pitch_link"/>
    <child link="l_hip_pitch_link"/>
    <origin rpy="0 0 0" xyz="0.06575 0.0245 0.000"/>
    <axis xyz="0 -1 0"/>
    <limit effort="9.90" lower="-0.7853981635" upper="0.7853981635" velocity="4.08"/>
    <!-- <limit velocity="4.08" effort="100" lower="-3" upper="3" /> -->
    <dynamics damping="0.1" friction="0.0"/>
    <implicitSpringDamper>True</implicitSpringDamper>
  </joint>
  <transmission name="l_hip_pitch_joint_tran">
    <type>transmission_interface/SimpleTransmission</type>
    <joint name="l_hip_pitch_joint">
      <hardwareInterface>hardware_interface/EffortJointInterface</hardwareInterface>
    </joint>
    <actuator name="l_hip_pitch_joint_motor">
      <hardwareInterface>hardware_interface/EffortJointInterface</hardwareInterface>
      <mechanicalReduction>1</mechanicalReduction>
    </actuator>
  </transmission>
  <link name="l_hip_pitch_link">
    <!-- <collision>
				<origin xyz="0.09 0.00 0.00" rpy="0.00 0.00 0.00"/>
				<geometry>
					<mesh filename="package://robinion_description/meshes/collision/l_hip_roll_pitch_collision.stl"/>
				</geometry>
			</collision> -->
    <visual>
      <origin rpy="0.00 0.00 0.00" xyz="0.00 0.00 0.00"/>
      <geometry>
        <mesh filename="package://robinion_description/meshes/visual/standard/left_hip_pitch_visual.stl"/>
      </geometry>
    </visual>
    <inertial>
      <origin rpy="0.00 0.00 0.00" xyz="0.045037 0.000333 -0.015045"/>
      <mass value="0.467377"/>
      <inertia ixx="0.000198" ixy="0.000003" ixz="0.000001" iyy="0.000406" iyz="0.000000" izz="0.000326"/>
    </inertial>
  </link>
  <joint name="l_knee_pitch_joint" type="revolute">
    <parent link="l_hip_pitch_link"/>
    <child link="l_knee_pitch_link"/>
    <origin rpy="0 0 0" xyz="0.000 0.000 -0.190"/>
    <axis xyz="0 -1 0"/>
    <limit effort="9.90" lower="-1.570796327" upper="1.570796327" velocity="4.08"/>
    <!-- <limit velocity="4.08" effort="100" lower="-3" upper="3" /> -->
    <dynamics damping="0.1" friction="0.0"/>
    <implicitSpringDamper>True</implicitSpringDamper>
  </joint>
  <transmission name="l_knee_pitch_joint_tran">
    <type>transmission_interface/SimpleTransmission</type>
    <joint name="l_knee_pitch_joint">
      <hardwareInterface>hardware_interface/EffortJointInterface</hardwareInterface>
    </joint>
    <actuator name="l_knee_pitch_joint_motor">
      <hardwareInterface>hardware_interface/EffortJointInterface</hardwareInterface>
      <mechanicalReduction>1</mechanicalReduction>
    </actuator>
  </transmission>
  <link name="l_knee_pitch_link">
    <!-- <collision>
				<origin xyz="0.00 0.00 0.00" rpy="0.00 0.00 0.00"/>
				<geometry>
					<mesh filename="package://robinion_description/meshes/collision/r_hip_yaw_collision.stl"/>
				</geometry>
			</collision> -->
    <visual>
      <origin rpy="0.00 0.00 0.00" xyz="0.00 0.00 0.00"/>
      <geometry>
        <mesh filename="package://robinion_description/meshes/visual/standard/left_leg_pitch_knee_ankle_visual.stl"/>
      </geometry>
    </visual>
    <inertial>
      <origin rpy="0.00 0.00 0.00" xyz="0.000420 -0.024035 -0.040918"/>
      <mass value="0.334780"/>
      <inertia ixx="0.000805" ixy="0.000000" ixz="-0.000012" iyy="0.000752" iyz="-0.000004" izz="0.000120"/>
    </inertial>
  </link>
  <joint name="l_ankle_pitch_joint" type="revolute">
    <parent link="l_knee_pitch_link"/>
    <child link="l_ankle_pitch_link"/>
    <origin rpy="0 0 0" xyz="0.000 0.000 -0.190"/>
    <axis xyz="0 -1 0"/>
    <limit effort="9.90" lower="-1.570796327" upper="1.570796327" velocity="4.08"/>
    <!-- <limit velocity="4.08" effort="100" lower="-3" upper="3" /> -->
    <dynamics damping="0.1" friction="0.0"/>
    <implicitSpringDamper>True</implicitSpringDamper>
  </joint>
  <transmission name="l_ankle_pitch_joint_tran">
    <type>transmission_interface/SimpleTransmission</type>
    <joint name="l_ankle_pitch_joint">
      <hardwareInterface>hardware_interface/EffortJointInterface</hardwareInterface>
    </joint>
    <actuator name="l_ankle_pitch_joint_motor">
      <hardwareInterface>hardware_interface/EffortJointInterface</hardwareInterface>
      <mechanicalReduction>1</mechanicalReduction>
    </actuator>
  </transmission>
  <link name="l_ankle_pitch_link">
    <!-- <collision>
				<origin xyz="0.00 0.00 0.00" rpy="0.00 0.00 0.00"/>
				<geometry>
					<mesh filename="package://robinion_description/meshes/collision/l_ankle_roll_pitch_collision.stl"/>
				</geometry>
			</collision> -->
    <visual>
      <origin rpy="0.00 0.00 0.00" xyz="0.00 0.00 0.00"/>
      <geometry>
        <mesh filename="package://robinion_description/meshes/visual/standard/left_ankle_roll_pitch_visual.stl"/>
      </geometry>
    </visual>
    <inertial>
      <origin rpy="0.00 0.00 0.00" xyz="-0.020713 -0.024167 0.015045"/>
      <mass value="0.467377"/>
      <inertia ixx="0.000198" ixy="-0.000003" ixz="0.000001" iyy="0.000406" iyz="-0.000000" izz="0.000326"/>
    </inertial>
  </link>
  <joint name="l_ankle_roll_joint" type="revolute">
    <parent link="l_ankle_pitch_link"/>
    <child link="l_foot_link"/>
    <origin rpy="0 0 0" xyz="-0.06575 -0.0245 0.000"/>
    <axis xyz="-1 0 0"/>
    <limit effort="9.90" lower="-1.570796327" upper="1.570796327" velocity="4.08"/>
    <!-- <limit velocity="4.08" effort="100" lower="-3" upper="3" /> -->
    <dynamics damping="0.1" friction="0.0"/>
    <implicitSpringDamper>True</implicitSpringDamper>
  </joint>
  <transmission name="l_ankle_roll_joint_tran">
    <type>transmission_interface/SimpleTransmission</type>
    <joint name="l_ankle_roll_joint">
      <hardwareInterface>hardware_interface/EffortJointInterface</hardwareInterface>
    </joint>
    <actuator name="l_ankle_roll_joint_motor">
      <hardwareInterface>hardware_interface/EffortJointInterface</hardwareInterface>
      <mechanicalReduction>1</mechanicalReduction>
    </actuator>
  </transmission>
  <link name="l_foot_link">
    <collision>
      <origin rpy="0.00 0.00 0.00" xyz="0.09 0.00 0.00"/>
      <geometry>
        <mesh filename="package://robinion_description/meshes/collision/l_foot_collision.stl"/>
      </geometry>
    </collision>
    <visual>
      <origin rpy="0.00 0.00 0.00" xyz="0.00 0.00 0.00"/>
      <geometry>
        <mesh filename="package://robinion_description/meshes/visual/standard/left_foot_visual.stl"/>
      </geometry>
    </visual>
    <inertial>
      <origin rpy="0.00 0.00 0.00" xyz="0.045052 0.011620 -0.047578"/>
      <mass value="0.241931"/>
      <inertia ixx="0.000290" ixy="-0.000000" ixz="0.000000" iyy="0.000663" iyz="-0.000010" izz="0.000899"/>
    </inertial>
  </link>
  <joint name="r_hip_yaw_joint" type="revolute">
    <parent link="base_link"/>
    <child link="r_hip_yaw_link"/>
    <origin rpy="0 0 0" xyz="0.000 -0.055 -0.006"/>
    <axis xyz="0 0 -1"/>
    <limit effort="10.6" lower="-2.8274333886000003" upper="2.8274333886000003" velocity="3.14"/>
    <!-- <limit velocity="3.14" effort="1000" lower="-3" upper="3" /> -->
    <dynamics damping="0.1" friction="0.0"/>
    <implicitSpringDamper>True</implicitSpringDamper>
  </joint>
  <transmission name="r_hip_yaw_joint_tran">
    <type>transmission_interface/SimpleTransmission</type>
    <joint name="r_hip_yaw_joint">
      <hardwareInterface>hardware_interface/EffortJointInterface</hardwareInterface>
    </joint>
    <actuator name="r_hip_yaw_joint_motor">
      <hardwareInterface>hardware_interface/EffortJointInterface</hardwareInterface>
      <mechanicalReduction>1</mechanicalReduction>
    </actuator>
  </transmission>
  <link name="r_hip_yaw_link">
    <collision>
      <origin rpy="0.00 0.00 0.00" xyz="0.00 0.00 0.00"/>
      <geometry>
        <mesh filename="package://robinion_description/meshes/collision/r_hip_yaw_collision.stl"/>
      </geometry>
    </collision>
    <visual>
      <origin rpy="0.00 0.00 0.00" xyz="0.00 0.00 0.00"/>
      <geometry>
        <mesh filename="package://robinion_description/meshes/visual/r_hip_yaw_visual.stl"/>
      </geometry>
    </visual>
    <inertial>
      <origin rpy="0.00 0.00 0.00" xyz="0.002613 0.000000 -0.016031"/>
      <mass value="0.467377"/>
      <inertia ixx="0.000020" ixy="0.000000" ixz="0.000000" iyy="0.000089" iyz="0.000000" izz="0.000080"/>
    </inertial>
  </link>
  <joint name="r_hip_roll_joint" type="revolute">
    <parent link="r_hip_yaw_link"/>
    <child link="r_hip_roll_pitch_link"/>
    <origin rpy="0 0 0" xyz="-0.042125 0.000 -0.050"/>
    <axis xyz="-1 0 0"/>
    <limit effort="9.90" lower="-0.7853981635" upper="0.7853981635" velocity="4.08"/>
    <!-- <limit velocity="4.08" effort="100" lower="-3" upper="3" /> -->
    <dynamics damping="0.1" friction="0.0"/>
    <implicitSpringDamper>True</implicitSpringDamper>
  </joint>
  <transmission name="r_hip_roll_joint_tran">
    <type>transmission_interface/SimpleTransmission</type>
    <joint name="r_hip_roll_joint">
      <hardwareInterface>hardware_interface/EffortJointInterface</hardwareInterface>
    </joint>
    <actuator name="r_hip_roll_joint_motor">
      <hardwareInterface>hardware_interface/EffortJointInterface</hardwareInterface>
      <mechanicalReduction>1</mechanicalReduction>
    </actuator>
  </transmission>
  <link name="r_hip_roll_pitch_link">
    <collision>
      <origin rpy="0.00 0.00 0.00" xyz="0.09 0.00 0.00"/>
      <geometry>
        <mesh filename="package://robinion_description/meshes/collision/r_hip_roll_pitch_collision.stl"/>
      </geometry>
    </collision>
    <visual>
      <origin rpy="0.00 0.00 0.00" xyz="0.00 0.00 0.00"/>
      <geometry>
        <mesh filename="package://robinion_description/meshes/visual/standard/right_hip_roll_pitch_visual.stl"/>
      </geometry>
    </visual>
    <inertial>
      <origin rpy="0.00 0.00 0.00" xyz="-0.020713 -0.024167 0.015045"/>
      <mass value="0.467377"/>
      <inertia ixx="0.000198" ixy="-0.000003" ixz="0.000001" iyy="0.000406" iyz="-0.000000" izz="0.000326"/>
    </inertial>
  </link>
  <joint name="r_hip_pitch_joint" type="revolute">
    <parent link="r_hip_roll_pitch_link"/>
    <child link="r_hip_pitch_link"/>
    <origin rpy="0 0 0" xyz="0.06575 -0.0245 0.000"/>
    <axis xyz="0 -1 0"/>
    <limit effort="9.90" lower="-1.570796327" upper="1.570796327" velocity="4.08"/>
    <!-- <limit velocity="4.08" effort="100" lower="-3" upper="3" /> -->
    <dynamics damping="0.1" friction="0.0"/>
    <implicitSpringDamper>True</implicitSpringDamper>
  </joint>
  <transmission name="r_hip_pitch_joint_tran">
    <type>transmission_interface/SimpleTransmission</type>
    <joint name="r_hip_pitch_joint">
      <hardwareInterface>hardware_interface/EffortJointInterface</hardwareInterface>
    </joint>
    <actuator name="r_hip_pitch_joint_motor">
      <hardwareInterface>hardware_interface/EffortJointInterface</hardwareInterface>
      <mechanicalReduction>1</mechanicalReduction>
    </actuator>
  </transmission>
  <link name="r_hip_pitch_link">
    <!-- <collision>
				<origin xyz="0.00 0.00 0.00" rpy="0.00 0.00 0.00"/>
				<geometry>
					<mesh filename="package://robinion_description/meshes/collision/r_hip_yaw_collision.stl"/>
				</geometry>
			</collision> -->
    <visual>
      <origin rpy="0.00 0.00 0.00" xyz="0.00 0.00 0.00"/>
      <geometry>
        <mesh filename="package://robinion_description/meshes/visual/standard/right_hip_pitch_visual.stl"/>
      </geometry>
    </visual>
    <inertial>
      <origin rpy="0.00 0.00 0.00" xyz="0.005543 -0.024500 -0.098751"/>
      <mass value="0.125336"/>
      <inertia ixx="0.000339" ixy="0.000000" ixz="-0.000026" iyy="0.000300" iyz="0.000000" izz="0.000084"/>
    </inertial>
  </link>
  <joint name="r_knee_pitch_joint" type="revolute">
    <parent link="r_hip_pitch_link"/>
    <child link="r_knee_pitch_link"/>
    <origin rpy="0 0 0" xyz="0.000 0.000 -0.190"/>
    <axis xyz="0 -1 0"/>
    <limit effort="9.90" lower="-1.570796327" upper="1.570796327" velocity="4.08"/>
    <!-- <limit velocity="4.08" effort="100" lower="-3" upper="3" /> -->
    <dynamics damping="0.1" friction="0.0"/>
    <implicitSpringDamper>True</implicitSpringDamper>
  </joint>
  <transmission name="r_knee_pitch_joint_tran">
    <type>transmission_interface/SimpleTransmission</type>
    <joint name="r_knee_pitch_joint">
      <hardwareInterface>hardware_interface/EffortJointInterface</hardwareInterface>
    </joint>
    <actuator name="r_knee_pitch_joint_motor">
      <hardwareInterface>hardware_interface/EffortJointInterface</hardwareInterface>
      <mechanicalReduction>1</mechanicalReduction>
    </actuator>
  </transmission>
  <link name="r_knee_pitch_link">
    <!-- <collision>
				<origin xyz="0.00 0.00 0.00" rpy="0.00 0.00 0.00"/>
				<geometry>
					<mesh filename="package://robinion_description/meshes/collision/r_hip_yaw_collision.stl"/>
				</geometry>
			</collision> -->
    <visual>
      <origin rpy="0.00 0.00 0.00" xyz="0.00 0.00 0.00"/>
      <geometry>
        <mesh filename="package://robinion_description/meshes/visual/standard/right_leg_pitch_knee_ankle_visual.stl"/>
      </geometry>
    </visual>
    <inertial>
      <origin rpy="0.00 0.00 0.00" xyz="0.000420 -0.024965 -0.040918"/>
      <mass value="0.334780"/>
      <inertia ixx="0.000805" ixy="0.000000" ixz="-0.000012" iyy="0.000752" iyz="-0.000004" izz="0.000120"/>
    </inertial>
  </link>
  <joint name="r_ankle_pitch_joint" type="revolute">
    <parent link="r_knee_pitch_link"/>
    <child link="r_ankle_pitch_link"/>
    <origin rpy="0 0 0" xyz="0.000 0.000 -0.190"/>
    <axis xyz="0 -1 0"/>
    <limit effort="9.90" lower="-1.570796327" upper="1.570796327" velocity="4.08"/>
    <!-- <limit velocity="4.08" effort="100" lower="-3" upper="3" /> -->
    <dynamics damping="0.1" friction="0.0"/>
    <implicitSpringDamper>True</implicitSpringDamper>
  </joint>
  <transmission name="r_ankle_pitch_joint_tran">
    <type>transmission_interface/SimpleTransmission</type>
    <joint name="r_ankle_pitch_joint">
      <hardwareInterface>hardware_interface/EffortJointInterface</hardwareInterface>
    </joint>
    <actuator name="r_ankle_pitch_joint_motor">
      <hardwareInterface>hardware_interface/EffortJointInterface</hardwareInterface>
      <mechanicalReduction>1</mechanicalReduction>
    </actuator>
  </transmission>
  <link name="r_ankle_pitch_link">
    <!-- <collision>
				<origin xyz="0.00 0.00 0.00" rpy="0.00 0.00 0.00"/>
				<geometry>
					<mesh filename="package://robinion_description/meshes/collision/r_ankle_roll_pitch_collision.stl"/>
				</geometry>
			</collision> -->
    <visual>
      <origin rpy="0.00 0.00 0.00" xyz="0.00 0.00 0.00"/>
      <geometry>
        <mesh filename="package://robinion_description/meshes/visual/standard/right_ankle_roll_pitch_visual.stl"/>
      </geometry>
    </visual>
    <inertial>
      <origin rpy="0.00 0.00 0.00" xyz="-0.020713 0.024167 0.015045"/>
      <mass value="0.467377"/>
      <inertia ixx="0.000198" ixy="-0.000003" ixz="0.000001" iyy="0.000406" iyz="-0.000000" izz="0.000326"/>
    </inertial>
  </link>
  <joint name="r_ankle_roll_joint" type="revolute">
    <parent link="r_ankle_pitch_link"/>
    <child link="r_foot_link"/>
    <origin rpy="0 0 0" xyz="-0.06575 0.0245 0.000"/>
    <axis xyz="-1 0 0"/>
    <limit effort="9.90" lower="-1.570796327" upper="1.570796327" velocity="4.08"/>
    <!-- <limit velocity="4.08" effort="100" lower="-3" upper="3" /> -->
    <dynamics damping="0.1" friction="0.0"/>
    <implicitSpringDamper>True</implicitSpringDamper>
  </joint>
  <transmission name="r_ankle_pitch_joint_tran">
    <type>transmission_interface/SimpleTransmission</type>
    <joint name="r_ankle_pitch_joint">
      <hardwareInterface>hardware_interface/EffortJointInterface</hardwareInterface>
    </joint>
    <actuator name="r_ankle_pitch_joint_motor">
      <hardwareInterface>hardware_interface/EffortJointInterface</hardwareInterface>
      <mechanicalReduction>1</mechanicalReduction>
    </actuator>
  </transmission>
  <link name="r_foot_link">
    <collision>
      <origin rpy="0.00 0.00 0.00" xyz="0.09 0.00 0.00"/>
      <geometry>
        <mesh filename="package://robinion_description/meshes/collision/r_foot_collision.stl"/>
      </geometry>
    </collision>
    <visual>
      <origin rpy="0.00 0.00 0.00" xyz="0.00 0.00 0.00"/>
      <geometry>
        <mesh filename="package://robinion_description/meshes/visual/standard/right_foot_visual.stl"/>
      </geometry>
    </visual>
    <inertial>
      <origin rpy="0.00 0.00 0.00" xyz="0.045052 -0.011620 -0.047578"/>
      <mass value="0.241931"/>
      <inertia ixx="0.000290" ixy="-0.000000" ixz="0.000000" iyy="0.000663" iyz="-0.000010" izz="0.000899"/>
    </inertial>
  </link>
  <!-- <link name="r_sole">
		</link> -->
</robot>

